Workbook

Sheet Tổng quan
A1: Checklist SRS – Hệ thống Lớp học Đảo ngược kết hợp Trợ giảng AI
A2: Nguồn: SRS_Flipped_Classroom_AI.docx (31 use case, 6 vai trò). Cột "Hiện trạng" là đánh giá ban đầu từ code; "Kết quả kiểm tra" để bạn tự tick.
A4: Vai trò | B4: Số hạng mục | C4: Đã có | D4: Một phần | E4: Chưa có | F4: Cần kiểm tra | G4: % đã có (tính một phần = 0,5) | H4: Đã kiểm "Đạt"
A5: Sinh viên | B5: =COUNTA('Sinh viên'!E:E)-1 -> 65 | C5: =COUNTIF('Sinh viên'!H:H,"Đã có") -> 29 | D5: =COUNTIF('Sinh viên'!H:H,"Một phần") -> 18 | E5: =COUNTIF('Sinh viên'!H:H,"Chưa có") -> 14 | F5: =COUNTIF('Sinh viên'!H:H,"Cần kiểm tra") -> 4 | G5: =IF(B5=0,0,(C5+0.5*D5)/B5) -> 0.58461538 | H5: =COUNTIF('Sinh viên'!J:J,"Đạt") -> 0
A6: Giảng viên | B6: =COUNTA('Giảng viên'!E:E)-1 -> 44 | C6: =COUNTIF('Giảng viên'!H:H,"Đã có") -> 18 | D6: =COUNTIF('Giảng viên'!H:H,"Một phần") -> 15 | E6: =COUNTIF('Giảng viên'!H:H,"Chưa có") -> 8 | F6: =COUNTIF('Giảng viên'!H:H,"Cần kiểm tra") -> 3 | G6: =IF(B6=0,0,(C6+0.5*D6)/B6) -> 0.57954545 | H6: =COUNTIF('Giảng viên'!J:J,"Đạt") -> 0
A7: Trưởng nhóm HP | B7: =COUNTA('Trưởng nhóm HP'!E:E)-1 -> 8 | C7: =COUNTIF('Trưởng nhóm HP'!H:H,"Đã có") -> 0 | D7: =COUNTIF('Trưởng nhóm HP'!H:H,"Một phần") -> 0 | E7: =COUNTIF('Trưởng nhóm HP'!H:H,"Chưa có") -> 8 | F7: =COUNTIF('Trưởng nhóm HP'!H:H,"Cần kiểm tra") -> 0 | G7: =IF(B7=0,0,(C7+0.5*D7)/B7) -> 0 | H7: =COUNTIF('Trưởng nhóm HP'!J:J,"Đạt") -> 0
A8: Trưởng khoa | B8: =COUNTA('Trưởng khoa'!E:E)-1 -> 4 | C8: =COUNTIF('Trưởng khoa'!H:H,"Đã có") -> 0 | D8: =COUNTIF('Trưởng khoa'!H:H,"Một phần") -> 0 | E8: =COUNTIF('Trưởng khoa'!H:H,"Chưa có") -> 4 | F8: =COUNTIF('Trưởng khoa'!H:H,"Cần kiểm tra") -> 0 | G8: =IF(B8=0,0,(C8+0.5*D8)/B8) -> 0 | H8: =COUNTIF('Trưởng khoa'!J:J,"Đạt") -> 0
A9: Admin | B9: =COUNTA(Admin!E:E)-1 -> 10 | C9: =COUNTIF(Admin!H:H,"Đã có") -> 0 | D9: =COUNTIF(Admin!H:H,"Một phần") -> 6 | E9: =COUNTIF(Admin!H:H,"Chưa có") -> 4 | F9: =COUNTIF(Admin!H:H,"Cần kiểm tra") -> 0 | G9: =IF(B9=0,0,(C9+0.5*D9)/B9) -> 0.3 | H9: =COUNTIF(Admin!J:J,"Đạt") -> 0
A10: Hệ thống AI | B10: =COUNTA('Hệ thống AI'!E:E)-1 -> 7 | C10: =COUNTIF('Hệ thống AI'!H:H,"Đã có") -> 2 | D10: =COUNTIF('Hệ thống AI'!H:H,"Một phần") -> 4 | E10: =COUNTIF('Hệ thống AI'!H:H,"Chưa có") -> 1 | F10: =COUNTIF('Hệ thống AI'!H:H,"Cần kiểm tra") -> 0 | G10: =IF(B10=0,0,(C10+0.5*D10)/B10) -> 0.57142857 | H10: =COUNTIF('Hệ thống AI'!J:J,"Đạt") -> 0
A11: Tổng | B11: =SUM(B5:B10) -> 138 | C11: =SUM(C5:C10) -> 49 | D11: =SUM(D5:D10) -> 43 | E11: =SUM(E5:E10) -> 39 | F11: =SUM(F5:F10) -> 7 | G11: =IF(B11=0,0,(C11+0.5*D11)/B11) -> 0.51086957 | H11: =SUM(H5:H10) -> 0
A13: Đánh giá độ đủ của SRS
A14: Đủ tốt: 3 giai đoạn (trước – trong – sau lớp) + vòng lặp liên tục; 31 use case có Normal Flow, Precondition, Postcondition, ma trận Actor – Use Case, 8 NFR.
A15: Thiếu nặng: không có danh sách màn hình / wireframe; không có yêu cầu chất lượng và an toàn AI; M0–M3 chưa định nghĩa; chưa nói về quyền riêng tư dữ liệu gửi AI.
A16: Mâu thuẫn cần chốt: tự đăng ký vs Admin cấp tài khoản; AI chấm tự động hoàn toàn vs GV duyệt; luyện tập AI không giới hạn vs chi phí credit.
A17: Chi tiết: sheet 'SRS còn thiếu' (16 mục) và 'Hệ thống có, SRS chưa có' (10 tính năng nên bổ sung vào SRS).

Sheet Sinh viên
A1: STT | B1: Mã | C1: Giai đoạn | D1: Use case | E1: Hạng mục kiểm tra | F1: Màn hình | G1: Ưu tiên (SRS) | H1: Hiện trạng hệ thống | I1: Ghi chú / vị trí | J1: Kết quả kiểm tra | K1: Người kiểm | L1: Ghi chú kiểm tra
A2: 1 | B2: SV-01 | C2: Chung | D2: UC-G04 Đăng nhập | E2: Đăng nhập bằng mã SV + mật khẩu | F2: Đăng nhập | G2: High | H2: Một phần | I2: Có trang đăng nhập; SRS yêu cầu đăng nhập bằng mã SV – cần kiểm tra trường đăng nhập | J2: Chưa kiểm
A3: 2 | B3: SV-02 | C3: Chung | D3: UC-G04 Đăng nhập | E3: Tài khoản do Admin cấp (không tự đăng ký) | F3: Đăng nhập | G3: High | H3: Một phần | I3: Hệ thống đang có trang Đăng ký tự do – khác SRS | J3: Chưa kiểm
A4: 3 | B4: SV-03 | C4: Chung | D4: UC-G04 Đăng nhập | E4: Đăng nhập lần đầu bắt buộc đổi mật khẩu mặc định (AF-2) | F4: Đổi mật khẩu | G4: High | H4: Chưa có | J4: Chưa kiểm
A5: 4 | B5: SV-04 | C5: Chung | D5: UC-G04 Đăng nhập | E5: Sai mật khẩu báo lỗi; quên mật khẩu → liên hệ Admin | F5: Đăng nhập | G5: High | H5: Một phần | I5: Có "Quên mật khẩu" qua OTP email – khác SRS (SRS: liên hệ Admin) | J5: Chưa kiểm
A6: 5 | B6: SV-05 | C6: Chung | D6: UC-G04 Đăng nhập | E6: Menu hiển thị theo role | F6: Sidebar | G6: High | H6: Đã có | I6: Sidebar tách menu SV / GV | J6: Chưa kiểm
A7: 6 | B7: SV-06 | C7: Trước lớp | D7: UC-B01 Phiên tự học AI | E7: Danh sách Phiên tự học AI theo học phần | F7: Danh sách phiên | G7: High | H7: Đã có | I7: Tab Tự học (study_hub) | J7: Chưa kiểm
A8: 7 | B8: SV-07 | C8: Trước lớp | D8: UC-B01 Phiên tự học AI | E8: Tổng quan phiên: tên bài, tiến độ, thời hạn, trạng thái | F8: Tổng quan phiên | G8: High | H8: Đã có | I8: study.js – trạng thái Chưa mở/Đang mở/Đã đóng | J8: Chưa kiểm
A9: 8 | B9: SV-08 | C9: Trước lớp | D9: UC-B01 Phiên tự học AI | E9: Nút "Bắt đầu học" / "Tiếp tục" | F9: Tổng quan phiên | G9: High | H9: Đã có | J9: Chưa kiểm
A10: 9 | B10: SV-09 | C10: Trước lớp | D10: UC-B01 Phiên tự học AI | E10: Hoàn thành 100% → "Completed", tính điểm tự học | F10: Tổng quan phiên | G10: High | H10: Một phần | I10: Có completed_at; điểm tự học theo công thức SRS chưa thấy | J10: Chưa kiểm
A11: 10 | B11: SV-10 | C11: Trước lớp | D11: UC-B01 Phiên tự học AI | E11: AF-1: Hết hạn vẫn xem được nhưng không tính điểm | F11: Tổng quan phiên | G11: High | H11: Một phần | I11: Có "Cho phép học muộn" + completed_late | J11: Chưa kiểm
A12: 11 | B12: SV-11 | C12: Trước lớp | D12: UC-B01 Phiên tự học AI | E12: AF-2: Đã hoàn thành vẫn vào xem lại để ôn | F12: Tổng quan phiên | G12: High | H12: Cần kiểm tra | J12: Chưa kiểm
A13: 12 | B13: SV-12 | C13: Trước lớp | D13: UC-B02 Xem slide | E13: Hiển thị slide + nút Trang trước / Trang sau | F13: Học slide | G13: High | H13: Đã có | I13: Trình đọc PDF | J13: Chưa kiểm
A14: 13 | B14: SV-13 | C14: Trước lớp | D14: UC-B02 Xem slide | E14: Thanh danh sách slide (thumbnail) bên trái | F14: Học slide | G14: High | H14: Chưa có | I14: Hiện có danh sách tuần/tài liệu, chưa có thumbnail từng slide | J14: Chưa kiểm
A15: 14 | B15: SV-14 | C15: Trước lớp | D15: UC-B02 Xem slide | E15: Ghi nhận slide đã xem để tính tiến độ | F15: Học slide | G15: High | H15: Đã có | I15: MaterialProgress / StudyProgress | J15: Chưa kiểm
A16: 15 | B16: SV-15 | C16: Trước lớp | D16: UC-B02 Xem slide | E16: Nút "Chat với AI" và "Hỏi trên lớp" dùng được mọi lúc | F16: Học slide | G16: High | H16: Đã có | J16: Chưa kiểm
A17: 16 | B17: SV-16 | C17: Trước lớp | D17: UC-B03 Pre-class quiz | E17: Slide có quiz phải trả lời mới qua slide tiếp | F17: Học slide | G17: High | H17: Đã có | I17: Phiên tự học: số câu bắt buộc/trang | J17: Chưa kiểm
A18: 17 | B18: SV-17 | C18: Trước lớp | D18: UC-B03 Pre-class quiz | E18: Trắc nghiệm A/B/C/D, bấm xác nhận | F18: Học slide | G18: High | H18: Đã có | J18: Chưa kiểm
A19: 18 | B19: SV-18 | C19: Trước lớp | D19: UC-B03 Pre-class quiz | E19: Hiện đúng/sai + giải thích ngay | F19: Học slide | G19: High | H19: Đã có | J19: Chưa kiểm
A20: 19 | B20: SV-19 | C20: Trước lớp | D20: UC-B03 Pre-class quiz | E20: AF-1: Sai vẫn cho đi tiếp nhưng ghi nhận | F20: Học slide | G20: High | H20: Đã có | J20: Chưa kiểm
A21: 20 | B21: SV-20 | C21: Trước lớp | D21: UC-B04 Chat với AI | E21: Panel chat mở từ màn học slide | F21: Học slide | G21: High | H21: Đã có | I21: Chat nổi, không làm co PDF | J21: Chưa kiểm
A22: 21 | B22: SV-21 | C22: Trước lớp | D22: UC-B04 Chat với AI | E22: Context = slide đang xem + toàn bộ học liệu lớp | F22: Học slide | G22: High | H22: Đã có | I22: RAG ưu tiên trang đang xem | J22: Chưa kiểm
A23: 22 | B23: SV-22 | C23: Trước lớp | D23: UC-B04 Chat với AI | E23: Hỏi nhiều lượt (multi-turn) | F23: Học slide | G23: High | H23: Đã có | J23: Chưa kiểm
A24: 23 | B24: SV-23 | C24: Trước lớp | D24: UC-B04 Chat với AI | E24: Lưu lịch sử chat | F24: Học slide | G24: High | H24: Đã có | J24: Chưa kiểm
A25: 24 | B25: SV-24 | C25: Trước lớp | D25: UC-B04 Chat với AI | E25: Có thể kèm câu hỏi mở khuyến khích tư duy | F25: Học slide | G25: High | H25: Một phần | I25: Không bắt buộc trong prompt | J25: Chưa kiểm
A26: 25 | B26: SV-25 | C26: Trước lớp | D26: UC-B04 Chat với AI | E26: AF-1: Đánh giá (rating/flag) câu trả lời | F26: Học slide | G26: High | H26: Đã có | I26: Chấm sao + báo lỗi | J26: Chưa kiểm
A27: 26 | B27: SV-26 | C27: Trước lớp | D27: UC-B04 Chat với AI | E27: EX-1: Ngoài phạm vi → "hãy hỏi giảng viên" | F27: Học slide | G27: High | H27: Đã có | I27: Chế độ insufficient / guardrail | J27: Chưa kiểm
A28: 27 | B28: SV-27 | C28: Trước lớp | D28: UC-B04 Chat với AI | E28: Disclaimer "Chat AI có thể mắc lỗi…" | F28: Học slide | G28: High | H28: Đã có | J28: Chưa kiểm
A29: 28 | B29: SV-28 | C29: Trước lớp | D29: UC-B05 Đánh dấu kiến thức mờ | E29: Nút "Hỏi trên lớp" tại slide đang xem | F29: Học slide | G29: Medium | H29: Đã có | I29: Trong Phiên tự học | J29: Chưa kiểm
A30: 29 | B30: SV-29 | C30: Trước lớp | D30: UC-B05 Đánh dấu kiến thức mờ | E30: Form tự gắn slide + ô nhập câu hỏi | F30: Modal | G30: Medium | H30: Đã có | J30: Chưa kiểm
A31: 30 | B31: SV-30 | C31: Trước lớp | D31: UC-B05 Đánh dấu kiến thức mờ | E31: Cập nhật số lượng kiến thức mờ | F31: Học slide | G31: Medium | H31: Cần kiểm tra | J31: Chưa kiểm
A32: 31 | B32: SV-31 | C32: Trước lớp | D32: UC-B06 Xem kiến thức mờ (SV) | E32: Popup "Kiến thức mờ (X)": nội dung, slide, ngày, trạng thái | F32: Popup | G32: Medium | H32: Cần kiểm tra | J32: Chưa kiểm
A33: 32 | B33: SV-32 | C33: Trước lớp | D33: UC-B06 Xem kiến thức mờ (SV) | E33: Bấm mục để nhảy tới slide | F33: Popup | G33: Medium | H33: Cần kiểm tra | J33: Chưa kiểm
A34: 33 | B34: SV-33 | C34: Trước lớp | D34: UC-B07 Câu hỏi luyện tập AI | E34: Nút "Tạo câu hỏi luyện tập", chọn phạm vi slide | F34: Luyện tập | G34: Medium | H34: Chưa có | I34: Hiện chỉ GV sinh câu hỏi AI | J34: Chưa kiểm
A35: 34 | B35: SV-34 | C35: Trước lớp | D35: UC-B07 Câu hỏi luyện tập AI | E35: AI sinh trắc nghiệm + điền trống kèm đáp án | F35: Luyện tập | G35: Medium | H35: Chưa có | I35: Có sẵn bộ sinh câu hỏi (question_gen) để tái sử dụng | J35: Chưa kiểm
A36: 35 | B36: SV-35 | C36: Trước lớp | D36: UC-B07 Câu hỏi luyện tập AI | E36: Quiz tương tác: đúng/sai + giải thích ngay; tổng kết; "Tạo bộ mới" | F36: Luyện tập | G36: Medium | H36: Chưa có | J36: Chưa kiểm
A37: 36 | B37: SV-36 | C37: Trước lớp | D37: UC-B07 Câu hỏi luyện tập AI | E37: Không tính điểm, không giới hạn lần | F37: Luyện tập | G37: Medium | H37: Chưa có | I37: Cần cân nhắc quota credit | J37: Chưa kiểm
A38: 37 | B38: SV-37 | C38: Trước lớp | D38: UC-B08 Tài liệu tham khảo | E38: Danh sách tài liệu: tên, mô tả, loại (File / Liên kết) | F38: Tài liệu TK | G38: Low | H38: Một phần | I38: Có tài liệu theo tuần (PDF/video); chưa có thư viện + liên kết | J38: Chưa kiểm
A39: 38 | B39: SV-38 | C39: Trước lớp | D39: UC-B08 Tài liệu tham khảo | E39: File → tải/mở; Liên kết → mở tab mới | F39: Tài liệu TK | G39: Low | H39: Một phần | J39: Chưa kiểm
A40: 39 | B40: SV-39 | C40: Trên lớp | D40: UC-C02 Trả lời trên lớp | E40: Tham gia bằng mã phiên hoặc quét QR | F40: Tham gia | G40: High | H40: Chưa có | I40: Hiện vào qua menu "Hỏi trên lớp" của lớp | J40: Chưa kiểm
...

Sheet Giảng viên
A1: STT | B1: Mã | C1: Giai đoạn | D1: Use case | E1: Hạng mục kiểm tra | F1: Màn hình | G1: Ưu tiên (SRS) | H1: Hiện trạng hệ thống | I1: Ghi chú / vị trí | J1: Kết quả kiểm tra | K1: Người kiểm | L1: Ghi chú kiểm tra
A2: 1 | B2: GV-01 | C2: Chuẩn bị | D2: UC-G02 Quản lý bài học | E2: Danh sách bài học trong lớp | F2: QL bài học | G2: High | H2: Một phần | I2: Hệ thống tổ chức theo tuần + tài liệu, chưa có thực thể "bài học" riêng | J2: Chưa kiểm
A3: 2 | B3: GV-02 | C3: Chuẩn bị | D3: UC-G02 Quản lý bài học | E3: Tạo / sửa: tên bài học, thứ tự | F3: QL bài học | G3: High | H3: Một phần | J3: Chưa kiểm
A4: 3 | B4: GV-03 | C4: Chuẩn bị | D4: UC-G02 Quản lý bài học | E4: Xoá bài học khi chưa có dữ liệu SV | F4: QL bài học | G4: High | H4: Cần kiểm tra | J4: Chưa kiểm
A5: 4 | B5: GV-04 | C5: Chuẩn bị | D5: UC-A01 Nội dung bài học | E5: Upload slide bài giảng | F5: Soạn nội dung | G5: High | H5: Đã có | I5: Upload PDF, có phiên bản | J5: Chưa kiểm
A6: 5 | B6: GV-05 | C6: Chuẩn bị | D6: UC-A01 Nội dung bài học | E6: Danh sách slide bên trái, preview bên phải | F6: Soạn nội dung | G6: High | H6: Một phần | J6: Chưa kiểm
A7: 6 | B7: GV-06 | C7: Chuẩn bị | D7: UC-A01 Nội dung bài học | E7: Thêm / xoá / sắp xếp từng slide | F7: Soạn nội dung | G7: High | H7: Chưa có | I7: Slide là 1 file PDF, không sửa từng trang | J7: Chưa kiểm
A8: 7 | B8: GV-07 | C8: Chuẩn bị | D8: UC-A01 Nội dung bài học | E8: Thêm video YouTube | F8: Soạn nội dung | G8: High | H8: Một phần | I8: Có upload video; chưa có nhúng YouTube | J8: Chưa kiểm
A9: 8 | B9: GV-08 | C9: Chuẩn bị | D9: UC-A01 Nội dung bài học | E9: Tạo câu hỏi quiz gắn từng slide (4 đáp án, đáp án đúng, giải thích) | F9: DS câu hỏi | G9: High | H9: Đã có | I9: Câu hỏi theo trang trong Phiên tự học | J9: Chưa kiểm
A10: 9 | B10: GV-09 | C10: Chuẩn bị | D10: UC-A01 Nội dung bài học | E10: "AI gợi ý câu hỏi" → GV rà soát, chỉnh sửa | F10: DS câu hỏi | G10: High | H10: Đã có | I10: Có duyệt bắt buộc + bằng chứng | J10: Chưa kiểm
A11: 10 | B11: GV-10 | C11: Chuẩn bị | D11: UC-A01 Nội dung bài học | E11: AF-1: Import / export câu hỏi Excel/CSV | F11: DS câu hỏi | G11: High | H11: Chưa có | J11: Chưa kiểm
A12: 11 | B12: GV-11 | C12: Chuẩn bị | D12: UC-A01 Nội dung bài học | E12: Câu hỏi dùng lại cho poll trên lớp | F12: DS câu hỏi | G12: High | H12: Đã có | I12: Hỏi trên lớp lấy từ phiên tự học / quiz | J12: Chưa kiểm
A13: 12 | B13: GV-12 | C13: Chuẩn bị | D13: UC-A02 Phiên tự học AI | E13: Đặt giờ bắt đầu – kết thúc | F13: Cài đặt phiên | G13: High | H13: Đã có | J13: Chưa kiểm
A14: 13 | B14: GV-13 | C14: Chuẩn bị | D14: UC-A02 Phiên tự học AI | E14: Tự Active khi đến giờ bắt đầu | F14: Cài đặt phiên | G14: High | H14: Đã có | J14: Chưa kiểm
A15: 14 | B15: GV-14 | C15: Chuẩn bị | D15: UC-A02 Phiên tự học AI | E15: AF-1: Gia hạn thời gian | F15: Cài đặt phiên | G15: High | H15: Cần kiểm tra | I15: Phiên đã công bố bị khoá cấu hình | J15: Chưa kiểm
A16: 15 | B16: GV-15 | C16: Chuẩn bị | D16: UC-A02 Phiên tự học AI | E16: AF-2: Thiết lập nhiều phiên | F16: Cài đặt phiên | G16: High | H16: Đã có | J16: Chưa kiểm
A17: 16 | B17: GV-16 | C17: Chuẩn bị | D17: UC-A03 Bài tập AI | E17: Cấu hình tiêu đề, thời gian làm, mở – đóng | F17: Bài tập AI | G17: High | H17: Đã có | J17: Chưa kiểm
A18: 17 | B18: GV-17 | C18: Chuẩn bị | D18: UC-A03 Bài tập AI | E18: Bố cục theo loại câu + điểm (VD TN 16 câu – 8đ…) | F18: Bài tập AI | G18: High | H18: Một phần | I18: Có điểm từng câu; chưa có cấu hình bố cục tổng | J18: Chưa kiểm
A19: 18 | B19: GV-18 | C19: Chuẩn bị | D19: UC-A03 Bài tập AI | E19: Chặn paste | F19: Bài tập AI | G19: High | H19: Đã có | J19: Chưa kiểm
A20: 19 | B20: GV-19 | C20: Chuẩn bị | D20: UC-A03 Bài tập AI | E20: "Tạo đề mới" có AI hỗ trợ → GV rà soát | F20: Bài tập AI | G20: High | H20: Đã có | I20: AI sinh trắc nghiệm; chưa sinh điền từ/tự luận | J20: Chưa kiểm
A21: 20 | B21: GV-20 | C21: Chuẩn bị | D21: UC-A03 Bài tập AI | E21: "Import đề" | F21: Bài tập AI | G21: High | H21: Chưa có | J21: Chưa kiểm
A22: 21 | B22: GV-21 | C22: Chuẩn bị | D22: UC-A03 Bài tập AI | E22: Nhiều đề, bật/tắt từng đề, ngẫu nhiên hoá | F22: Bài tập AI | G22: High | H22: Chưa có | J22: Chưa kiểm
A23: 22 | B23: GV-22 | C23: Chuẩn bị | D23: UC-A04 Tài liệu tham khảo | E23: Thêm tài liệu: upload file hoặc dán liên kết | F23: QL tài liệu TK | G23: Low | H23: Một phần | I23: Có upload; chưa có liên kết | J23: Chưa kiểm
A24: 23 | B24: GV-23 | C24: Chuẩn bị | D24: UC-A04 Tài liệu tham khảo | E24: Tiêu đề, mô tả ngắn; sắp xếp, sửa, xoá | F24: QL tài liệu TK | G24: Low | H24: Một phần | J24: Chưa kiểm
A25: 24 | B25: GV-24 | C25: Trên lớp | D25: UC-C01 Chiếu câu hỏi | E25: Bấm "Hỏi trên lớp" → chọn câu hỏi, chọn lớp | F25: Màn chiếu | G25: High | H25: Đã có | I25: Tạo phiên Hỏi trên lớp theo lớp | J25: Chưa kiểm
A26: 25 | B26: GV-25 | C26: Trên lớp | D26: UC-C01 Chiếu câu hỏi | E26: Màn chiếu: câu hỏi + 4 đáp án + đếm ngược | F26: Màn chiếu | G26: High | H26: Đã có | I26: Có nút Toàn màn hình | J26: Chưa kiểm
A27: 26 | B27: GV-26 | C27: Trên lớp | D27: UC-C01 Chiếu câu hỏi | E27: Mã phiên (số ngắn) + mã QR | F27: Màn chiếu | G27: High | H27: Chưa có | J27: Chưa kiểm
A28: 27 | B28: GV-27 | C28: Trên lớp | D28: UC-C01 Chiếu câu hỏi | E28: "Đổi câu hỏi" chuyển câu | F28: Màn chiếu | G28: High | H28: Đã có | I28: "Câu tiếp" | J28: Chưa kiểm
A29: 28 | B29: GV-28 | C29: Trên lớp | D29: UC-C01 Chiếu câu hỏi | E29: Hết giờ hoặc tất cả đã trả lời → hiện kết quả | F29: Màn chiếu | G29: High | H29: Một phần | I29: GV bấm "Hiện đáp án"; chưa tự động | J29: Chưa kiểm
A30: 29 | B30: GV-29 | C30: Trên lớp | D30: UC-C03 Kết quả real-time | E30: Số SV đã trả lời | F30: Màn chiếu | G30: Medium | H30: Đã có | J30: Chưa kiểm
A31: 30 | B31: GV-30 | C31: Trên lớp | D31: UC-C03 Kết quả real-time | E31: Phân bố từng đáp án, tỷ lệ đúng | F31: Màn chiếu | G31: Medium | H31: Đã có | I31: Biểu đồ thanh | J31: Chưa kiểm
A32: 31 | B32: GV-31 | C32: Trên lớp | D32: UC-C04 Kiến thức mờ (GV) | E32: Popup danh sách, gom theo slide + số lượng | F32: Popup | G32: Medium | H32: Một phần | I32: Có số thắc mắc chưa giải đáp theo trang trong báo cáo phiên | J32: Chưa kiểm
A33: 32 | B33: GV-32 | C33: Trên lớp | D33: UC-C04 Kiến thức mờ (GV) | E33: Đánh dấu "Đã giải thích" từng mục hoặc cả nhóm | F33: Popup | G33: Medium | H33: Cần kiểm tra | I33: Có trường resolved_at | J33: Chưa kiểm
A34: 33 | B34: GV-33 | C34: Giám sát | D34: UC-F01 Dashboard | E34: Tiến độ tự học từng SV (tên, email, bài, % hoàn thành) | F34: Dashboard | G34: High | H34: Đã có | I34: Báo cáo phiên tự học + CSV | J34: Chưa kiểm
A35: 34 | B35: GV-34 | C35: Giám sát | D35: UC-F01 Dashboard | E35: Kết quả bài tập: điểm, % đúng, thời gian nộp | F35: Dashboard | G35: High | H35: Một phần | J35: Chưa kiểm
A36: 35 | B36: GV-35 | C36: Giám sát | D36: UC-F01 Dashboard | E36: Tương tác: Chat AI, quiz trên lớp, phản hồi | F36: Dashboard | G36: High | H36: Một phần | I36: Có dữ liệu, chưa gom vào một dashboard | J36: Chưa kiểm
A37: 36 | B37: GV-36 | C37: Giám sát | D37: UC-F01 Dashboard | E37: Phân tích AI: nội dung sai nhiều, đề xuất | F37: Dashboard | G37: High | H37: Đã có | I37: Gợi ý buổi học (AI) | J37: Chưa kiểm
A38: 37 | B38: GV-37 | C38: Giám sát | D38: UC-F01 Dashboard | E38: Cảnh báo SV tiến độ thấp / điểm dưới ngưỡng | F38: Dashboard | G38: High | H38: Đã có | I38: Trang Cảnh báo + nút Nhắc | J38: Chưa kiểm
A39: 38 | B39: GV-38 | C39: Điểm số | D39: UC-G01 Xem và xuất điểm | E39: Bảng: STT, Mã SV, Họ đệm, Tên, Điểm tự học, Điểm TB bài tập | F39: Bảng điểm | G39: High | H39: Một phần | J39: Chưa kiểm
A40: 39 | B40: GV-39 | C40: Điểm số | D40: UC-G01 Xem và xuất điểm | E40: Xuất Excel | F40: Bảng điểm | G40: High | H40: Một phần | I40: Có xuất CSV ở báo cáo phiên tự học | J40: Chưa kiểm
...

Sheet Trưởng nhóm HP
A1: STT | B1: Mã | C1: Giai đoạn | D1: Use case | E1: Hạng mục kiểm tra | F1: Màn hình | G1: Ưu tiên (SRS) | H1: Hiện trạng hệ thống | I1: Ghi chú / vị trí | J1: Kết quả kiểm tra | K1: Người kiểm | L1: Ghi chú kiểm tra
A2: 1 | B2: TN-01 | C2: Chung | D2: UC-G04 Đăng nhập | E2: Đăng nhập với role CourseLeader | F2: Đăng nhập | G2: High | H2: Chưa có | I2: Hệ thống chưa có role này | J2: Chưa kiểm
A3: 2 | B3: TN-02 | C3: Chuẩn bị | D3: UC-A05 Chuẩn hoá học liệu | E3: Danh sách các lớp cùng học phần | F3: Chuẩn hoá | G3: High | H3: Chưa có | J3: Chưa kiểm
A4: 3 | B4: TN-03 | C4: Chuẩn bị | D4: UC-A05 Chuẩn hoá học liệu | E4: Rà soát slide, quiz, đề bài tập từng lớp | F4: Chuẩn hoá | G4: High | H4: Chưa có | J4: Chưa kiểm
A5: 4 | B5: TN-04 | C5: Chuẩn bị | D5: UC-A05 Chuẩn hoá học liệu | E5: So sánh giữa các lớp, yêu cầu GV điều chỉnh | F5: Chuẩn hoá | G5: High | H5: Chưa có | J5: Chưa kiểm
A6: 5 | B6: TN-05 | C6: Chuẩn bị | D6: UC-A05 Chuẩn hoá học liệu | E6: Cụ thể hoá mức xử lý M0–M3 | F6: Chuẩn hoá | G6: High | H6: Chưa có | I6: SRS chưa định nghĩa M0–M3 | J6: Chưa kiểm
A7: 6 | B7: TN-06 | C7: Chuẩn bị | D7: UC-A05 Chuẩn hoá học liệu | E7: Đánh dấu "Hoàn thành chuẩn hoá" | F7: Chuẩn hoá | G7: High | H7: Chưa có | J7: Chưa kiểm
A8: 7 | B8: TN-07 | C8: Chuẩn bị | D8: UC-A05 Chuẩn hoá học liệu | E8: AF-1: Sửa trực tiếp nội dung nếu có quyền | F8: Chuẩn hoá | G8: High | H8: Chưa có | J8: Chưa kiểm
A9: 8 | B9: TN-08 | C9: Chuẩn bị | D9: UC-A01/A03/A04 (phụ) | E9: Tạo / sửa nội dung, bài tập, tài liệu như GV | F9: Như GV | G9: High | H9: Chưa có | J9: Chưa kiểm

Sheet Trưởng khoa
A1: STT | B1: Mã | C1: Giai đoạn | D1: Use case | E1: Hạng mục kiểm tra | F1: Màn hình | G1: Ưu tiên (SRS) | H1: Hiện trạng hệ thống | I1: Ghi chú / vị trí | J1: Kết quả kiểm tra | K1: Người kiểm | L1: Ghi chú kiểm tra
A2: 1 | B2: TK-01 | C2: Chung | D2: UC-G04 Đăng nhập | E2: Đăng nhập với role Dean | F2: Đăng nhập | G2: High | H2: Chưa có | J2: Chưa kiểm
A3: 2 | B3: TK-02 | C3: Giám sát | D3: UC-F01 Dashboard khoa | E3: Tổng quan toàn khoa | F3: Dashboard khoa | G3: High | H3: Chưa có | J3: Chưa kiểm
A4: 3 | B4: TK-03 | C4: Giám sát | D4: UC-F01 Dashboard khoa | E4: Drill-down: học phần → lớp | F4: Dashboard khoa | G4: High | H4: Chưa có | J4: Chưa kiểm
A5: 4 | B5: TK-04 | C5: Giám sát | D5: UC-F01 Dashboard khoa | E5: Mức hoàn thành, cảnh báo SV yếu toàn khoa | F5: Dashboard khoa | G5: High | H5: Chưa có | I5: Có thể tái dùng logic Cảnh báo sớm theo lớp | J5: Chưa kiểm

Sheet Admin
A1: STT | B1: Mã | C1: Giai đoạn | D1: Use case | E1: Hạng mục kiểm tra | F1: Màn hình | G1: Ưu tiên (SRS) | H1: Hiện trạng hệ thống | I1: Ghi chú / vị trí | J1: Kết quả kiểm tra | K1: Người kiểm | L1: Ghi chú kiểm tra
A2: 1 | B2: AD-01 | C2: Chung | D2: UC-G04 Đăng nhập | E2: Đăng nhập Admin | F2: Đăng nhập | G2: High | H2: Một phần | I2: Có Django admin | J2: Chưa kiểm
A3: 2 | B3: AD-02 | C3: Quản lý | D3: UC-G05 Tài khoản | E3: Import SV từ Excel (Mã SV, Họ tên, Email) → mật khẩu mặc định | F3: QL tài khoản | G3: High | H3: Chưa có | I3: Có lệnh import dữ liệu VJU, chưa có giao diện | J3: Chưa kiểm
A4: 3 | B4: AD-03 | C4: Quản lý | D4: UC-G05 Tài khoản | E4: Import GV từ Excel (Mã GV, Họ tên, Email, Khoa) | F4: QL tài khoản | G4: High | H4: Chưa có | J4: Chưa kiểm
A5: 4 | B5: AD-04 | C5: Quản lý | D5: UC-G05 Tài khoản | E5: Gán role CourseLeader / Dean | F5: QL tài khoản | G5: High | H5: Chưa có | J5: Chưa kiểm
A6: 5 | B6: AD-05 | C6: Quản lý | D6: UC-G05 Tài khoản | E6: Reset mật khẩu về mặc định | F6: QL tài khoản | G6: High | H6: Một phần | I6: Qua Django admin | J6: Chưa kiểm
A7: 6 | B7: AD-06 | C7: Quản lý | D7: UC-G05 Tài khoản | E7: Vô hiệu hoá tài khoản (không xoá dữ liệu) | F7: QL tài khoản | G7: High | H7: Một phần | I7: Qua Django admin (is_active) | J7: Chưa kiểm
A8: 7 | B8: AD-07 | C8: Quản lý | D8: UC-G06 Học phần & lớp | E8: Tạo / sửa học phần (Mã, Tên, Khoa) | F8: QL học phần | G8: High | H8: Một phần | I8: GV tự tạo lớp; chưa có thực thể học phần riêng | J8: Chưa kiểm
A9: 8 | B9: AD-08 | C9: Quản lý | D9: UC-G06 Học phần & lớp | E9: Tạo lớp (Tên, Học kỳ, Năm học, Đợt) | F9: QL học phần | G9: High | H9: Một phần | I9: Có học kỳ / năm học | J9: Chưa kiểm
A10: 9 | B10: AD-09 | C10: Quản lý | D10: UC-G06 Học phần & lớp | E10: Gán GV, gán Trưởng nhóm HP | F10: QL học phần | G10: High | H10: Một phần | I10: Gán GV có; Trưởng nhóm chưa | J10: Chưa kiểm
A11: 10 | B11: AD-10 | C11: Quản lý | D11: UC-G06 Học phần & lớp | E11: Import danh sách SV vào lớp | F11: QL học phần | G11: High | H11: Chưa có | J11: Chưa kiểm

Sheet Hệ thống AI
A1: STT | B1: Mã | C1: Giai đoạn | D1: Use case | E1: Hạng mục kiểm tra | F1: Màn hình | G1: Ưu tiên (SRS) | H1: Hiện trạng hệ thống | I1: Ghi chú / vị trí | J1: Kết quả kiểm tra | K1: Người kiểm | L1: Ghi chú kiểm tra
A2: 1 | B2: AI-01 | C2: Trước lớp | D2: UC-B04 (phụ) | E2: Trả lời chatbot có trích dẫn từ học liệu | F2: — | G2: High | H2: Đã có | I2: RAG + kiểm tra trích dẫn + guardrail | J2: Chưa kiểm
A3: 2 | B3: AI-02 | C3: Trước lớp | D3: UC-B07 (phụ) | E3: Sinh câu hỏi luyện tập từ slide | F3: — | G3: Medium | H3: Một phần | I3: Có cho GV; chưa mở cho SV | J3: Chưa kiểm
A4: 3 | B4: AI-03 | C4: Sau lớp | D4: UC-D01 (phụ) | E4: Chấm bài tự động + giải thích + phản hồi cá nhân | F4: — | G4: High | H4: Một phần | I4: Tự luận: AI chấm nháp, GV duyệt | J4: Chưa kiểm
A5: 4 | B5: AI-04 | C5: Giám sát | D5: UC-F01 (phụ) | E5: Phân tích dữ liệu, nhận diện vùng yếu, đề xuất | F5: — | G5: High | H5: Đã có | I5: Gợi ý buổi học, hồ sơ người học, cảnh báo sớm | J5: Chưa kiểm
A6: 5 | B6: AI-05 | C6: Chung | D6: UC-G03 Nhắc deadline | E6: Quét deadline phiên tự học / bài tập 24 giờ trước | F6: Cron | G6: Medium | H6: Một phần | I6: Có thông báo trong hệ thống (sync_learning_notifications) | J6: Chưa kiểm
A7: 6 | B7: AI-06 | C7: Chung | D7: UC-G03 Nhắc deadline | E7: Gửi email: tên SV, lớp, bài, hạn, tiến độ | F7: Email | G7: Medium | H7: Chưa có | J7: Chưa kiểm
A8: 7 | B8: AI-07 | C8: Chung | D8: UC-G03 Nhắc deadline | E8: Lưu bản ghi nhắc nhở | F8: — | G8: Medium | H8: Một phần | I8: Notification có event_key | J8: Chưa kiểm

Sheet Phi chức năng (NFR)
A1: Mã | B1: Yêu cầu | C1: Loại | D1: Hiện trạng hệ thống | E1: Ghi chú | F1: Kết quả kiểm tra | G1: Người kiểm
A2: NFR-01 | B2: Tối thiểu 500 người dùng đồng thời | C2: Performance | D2: Cần kiểm tra | E2: Chưa kiểm thử tải; đang dùng SQLite khi chạy local | F2: Chưa kiểm
A3: NFR-02 | B3: Xem slide, trả lời quiz ≤ 2 giây | C3: Performance | D3: Cần kiểm tra | F3: Chưa kiểm
A4: NFR-03 | B4: AI chấm tự luận ≤ 30 giây/bài | C4: Performance | D4: Đã có | E4: Chạy thật ~5–8 giây/bài | F4: Chưa kiểm
A5: NFR-04 | B5: Uptime ≥ 99,5%, 24/7 | C5: Availability | D5: Chưa có | E5: Phụ thuộc triển khai | F5: Chưa kiểm
A6: NFR-05 | B6: Responsive máy tính + điện thoại | C6: Usability | D6: Một phần | F6: Chưa kiểm
A7: NFR-06 | B7: Mã hoá khi truyền (HTTPS/TLS) và khi lưu | C7: Security | D7: Cần kiểm tra | E7: Phụ thuộc triển khai | F7: Chưa kiểm
A8: NFR-07 | B8: Mở rộng thêm ngành / học phần | C8: Scalability | D8: Một phần | F8: Chưa kiểm
A9: NFR-08 | B9: Disclaimer Chat AI | C9: Compliance | D9: Đã có | F9: Chưa kiểm

Sheet SRS còn thiếu
A1: STT | B1: Mức độ | C1: Nhóm | D1: Vấn đề trong SRS | E1: Đề xuất bổ sung | F1: Đã bổ sung vào SRS?
A2: 1 | B2: Cao | C2: Giao diện | D2: Không có danh sách màn hình / sitemap / wireframe; UI chỉ nằm rải rác trong Normal Flow | E2: Thêm mục "UI Screen Inventory": ~27 màn hình chính + 6 popup, ghi UC liên quan | F2: Chưa
A3: 2 | B3: Cao | C3: AI | D3: Không có yêu cầu chất lượng AI: độ đúng, bám nguồn, trích dẫn, tỉ lệ bịa | E3: Thêm NFR AI dựa trên docs/eval/TIEU_CHI_DANH_GIA_AI.md (Q1–Q6, S1–S3) | F3: Chưa
A4: 3 | B4: Cao | C4: AI | D4: Không quy định chống làm bài hộ / lộ đáp án quiz khi sinh viên hỏi Chat AI | E4: Thêm Business Rule: Chat AI không giải bài tập/quiz đang mở cho sinh viên | F4: Chưa
A5: 4 | B5: Cao | C5: AI | D5: BR-02 cho AI chấm tự động hoàn toàn; không có người duyệt trước khi công bố điểm tự luận | E5: Cân nhắc: AI chấm nháp – GV duyệt (hệ thống hiện làm vậy) hoặc ghi rõ ngưỡng cần duyệt | F5: Chưa
A6: 5 | B6: Cao | C6: Nghiệp vụ | D6: M0–M3 được nhắc trong BR-07, UC-A05 nhưng không định nghĩa | E6: Định nghĩa từng mức xử lý kết quả Bài tập AI | F6: Chưa
A7: 6 | B7: Cao | C7: Dữ liệu | D7: Không có yêu cầu quyền riêng tư: dữ liệu SV gửi lên AI bên ngoài, lưu lịch sử chat bao lâu | E7: Thêm NFR: ẩn danh khi gửi AI, thời hạn lưu, SV xem/xoá dữ liệu cá nhân hoá | F7: Chưa
A8: 7 | B8: Trung bình | C8: AI | D8: Không có giới hạn chi phí AI (quota lượt hỏi/ngày, ngân sách credit) | E8: Thêm NFR quota và theo dõi chi phí (hệ thống đã có: 40 lượt/SV/ngày, trang Thống kê AI) | F8: Chưa
A9: 8 | B9: Trung bình | C9: AI | D9: Không quy định nội dung AI sinh (câu hỏi, đề) phải được GV duyệt | E9: Thêm BR: nội dung AI sinh cần duyệt trước khi SV thấy | F9: Chưa
A10: 9 | B10: Trung bình | C10: Nghiệp vụ | D10: Khái niệm "bài học", "phiên tự học", "slide" chưa có quan hệ rõ (1 bài học có mấy phiên?) | E10: Thêm sơ đồ thực thể / glossary | F10: Chưa
A11: 10 | B11: Trung bình | C11: Nghiệp vụ | D11: UC-B07 (luyện tập không giới hạn) mâu thuẫn với chi phí AI | E11: Giới hạn số bộ/ngày hoặc dùng ngân hàng câu hỏi có sẵn | F11: Chưa
A12: 11 | B12: Trung bình | C12: Giao diện | D12: Không mô tả trạng thái lỗi / rỗng / đang tải cho từng màn | E12: Bổ sung empty/error/loading states | F12: Chưa
A13: 12 | B13: Trung bình | C13: Thông báo | D13: Chỉ có email (UC-G03); không có thông báo trong hệ thống, không có thông báo cho GV khi có phúc khảo/phản hồi (chỉ ghi "GV nhận thông báo") | E13: Định nghĩa kênh thông báo (in-app, email) cho từng sự kiện | F13: Chưa
... A17: 16 | B17: Thấp | C17: Khả năng tiếp cận | D17: Không có yêu cầu accessibility (bàn phím, trình đọc màn hình, TTS) | E17: Thêm NFR accessibility (WCAG AA) | F17: Chưa

Sheet Hệ thống có, SRS chưa có
A1: STT | B1: Tính năng | C1: Mô tả | D1: Đưa vào SRS?
A2: 1 | B2: Bài giảng AI | C2: Giải thích từng trang slide do AI soạn, GV duyệt/công bố; mục lục video có mốc thời gian | D2: Chưa
A3: 2 | B3: Nghe bài giảng | C3: Đọc to Bài giảng AI (Web Speech), tốc độ, tự sang trang | D3: Chưa
A4: 3 | B4: Cá nhân hoá | C4: Hồ sơ người học gửi kèm Chat AI, ô "AI biết gì về em?", tắt cá nhân hoá, trang nên xem lại | D4: Chưa
A5: 4 | B5: Cảnh báo sớm | C5: Trang Cảnh báo học tập + nút Nhắc + xuất CSV | D5: Chưa
A6: 5 | B6: Gợi ý buổi học | C6: AI gợi ý chủ đề khó, câu thảo luận, hoạt động cho buổi học trên lớp | D6: Chưa
A7: 6 | B7: Thống kê AI | C7: Lần gọi, token theo tính năng/model/ngày; xuất CSV | D7: Chưa
A8: 7 | B8: Đánh chỉ mục AI | C8: Đánh chỉ mục PDF (chữ + mô tả hình) và video (chép lời) khi công bố | D8: Chưa
A9: 8 | B9: Video | C9: Chat AI trích dẫn mốc giây trong video, bấm để tua | D9: Chưa
A10: 9 | B10: Công thức | C10: Hiển thị công thức LaTeX (KaTeX) trong mọi nội dung AI | D10: Chưa
A11: 10 | B11: Tracing | C11: Phoenix tracing cho pipeline AI | D11: Chưa
